2020-04-10 23:56:51,929 ERROR: Exception on /index [GET] [in c:\users\gk616ph\documents\data analytics\python\flask projects\microblog\env\lib\site-packages\flask\app.py:1891]
Traceback (most recent call last):
  File "c:\users\gk616ph\documents\data analytics\python\flask projects\microblog\env\lib\site-packages\flask\app.py", line 2446, in wsgi_app
    response = self.full_dispatch_request()
  File "c:\users\gk616ph\documents\data analytics\python\flask projects\microblog\env\lib\site-packages\flask\app.py", line 1951, in full_dispatch_request
    rv = self.handle_user_exception(e)
  File "c:\users\gk616ph\documents\data analytics\python\flask projects\microblog\env\lib\site-packages\flask\app.py", line 1820, in handle_user_exception
    reraise(exc_type, exc_value, tb)
  File "c:\users\gk616ph\documents\data analytics\python\flask projects\microblog\env\lib\site-packages\flask\_compat.py", line 39, in reraise
    raise value
  File "c:\users\gk616ph\documents\data analytics\python\flask projects\microblog\env\lib\site-packages\flask\app.py", line 1949, in full_dispatch_request
    rv = self.dispatch_request()
  File "c:\users\gk616ph\documents\data analytics\python\flask projects\microblog\env\lib\site-packages\flask\app.py", line 1935, in dispatch_request
    return self.view_functions[rule.endpoint](**req.view_args)
  File "c:\users\gk616ph\documents\data analytics\python\flask projects\microblog\env\lib\site-packages\flask_login\utils.py", line 272, in decorated_view
    return func(*args, **kwargs)
  File "C:\Users\GK616PH\Documents\Data Analytics\Python\Flask projects\microblog\app\routes.py", line 30, in index
    page, app.config['POSTS_PER_PAGE'], False)
  File "c:\users\gk616ph\documents\data analytics\python\flask projects\microblog\env\lib\site-packages\flask\templating.py", line 138, in render_template
    ctx.app.jinja_env.get_or_select_template(template_name_or_list),
  File "c:\users\gk616ph\documents\data analytics\python\flask projects\microblog\env\lib\site-packages\jinja2\environment.py", line 930, in get_or_select_template
    return self.get_template(template_name_or_list, parent, globals)
  File "c:\users\gk616ph\documents\data analytics\python\flask projects\microblog\env\lib\site-packages\jinja2\environment.py", line 883, in get_template
    return self._load_template(name, self.make_globals(globals))
  File "c:\users\gk616ph\documents\data analytics\python\flask projects\microblog\env\lib\site-packages\jinja2\environment.py", line 857, in _load_template
    template = self.loader.load(self, name, globals)
  File "c:\users\gk616ph\documents\data analytics\python\flask projects\microblog\env\lib\site-packages\jinja2\loaders.py", line 129, in load
    code = environment.compile(source, name, filename)
  File "c:\users\gk616ph\documents\data analytics\python\flask projects\microblog\env\lib\site-packages\jinja2\environment.py", line 638, in compile
    self.handle_exception(source=source_hint)
  File "c:\users\gk616ph\documents\data analytics\python\flask projects\microblog\env\lib\site-packages\jinja2\environment.py", line 832, in handle_exception
    reraise(*rewrite_traceback_stack(source=source))
  File "c:\users\gk616ph\documents\data analytics\python\flask projects\microblog\env\lib\site-packages\jinja2\_compat.py", line 28, in reraise
    raise value.with_traceback(tb)
  File "C:\Users\GK616PH\Documents\Data Analytics\Python\Flask projects\microblog\app\templates\index.html", line 19, in template
    {% include '_post.html %}
jinja2.exceptions.TemplateSyntaxError: unexpected char "'" at 532
2020-04-11 00:00:47,007 INFO: Microblog startup [in C:\Users\GK616PH\Documents\Data Analytics\Python\Flask projects\microblog\app\__init__.py:43]
