2020-04-12 21:46:24,032 ERROR: Exception on /login [GET] [in c:\users\gk616ph\documents\data analytics\python\flask projects\microblog\env\lib\site-packages\flask\app.py:1891]
Traceback (most recent call last):
  File "c:\users\gk616ph\documents\data analytics\python\flask projects\microblog\env\lib\site-packages\flask\app.py", line 2446, in wsgi_app
    response = self.full_dispatch_request()
  File "c:\users\gk616ph\documents\data analytics\python\flask projects\microblog\env\lib\site-packages\flask\app.py", line 1951, in full_dispatch_request
    rv = self.handle_user_exception(e)
  File "c:\users\gk616ph\documents\data analytics\python\flask projects\microblog\env\lib\site-packages\flask\app.py", line 1820, in handle_user_exception
    reraise(exc_type, exc_value, tb)
  File "c:\users\gk616ph\documents\data analytics\python\flask projects\microblog\env\lib\site-packages\flask\_compat.py", line 39, in reraise
    raise value
  File "c:\users\gk616ph\documents\data analytics\python\flask projects\microblog\env\lib\site-packages\flask\app.py", line 1949, in full_dispatch_request
    rv = self.dispatch_request()
  File "c:\users\gk616ph\documents\data analytics\python\flask projects\microblog\env\lib\site-packages\flask\app.py", line 1935, in dispatch_request
    return self.view_functions[rule.endpoint](**req.view_args)
  File "C:\Users\GK616PH\Documents\Data Analytics\Python\Flask projects\microblog\app\routes.py", line 69, in login
    return render_template('login.html', title='Sign In', form=form)
  File "c:\users\gk616ph\documents\data analytics\python\flask projects\microblog\env\lib\site-packages\flask\templating.py", line 140, in render_template
    ctx.app,
  File "c:\users\gk616ph\documents\data analytics\python\flask projects\microblog\env\lib\site-packages\flask\templating.py", line 120, in _render
    rv = template.render(context)
  File "c:\users\gk616ph\documents\data analytics\python\flask projects\microblog\env\lib\site-packages\jinja2\environment.py", line 1090, in render
    self.environment.handle_exception()
  File "c:\users\gk616ph\documents\data analytics\python\flask projects\microblog\env\lib\site-packages\jinja2\environment.py", line 832, in handle_exception
    reraise(*rewrite_traceback_stack(source=source))
  File "c:\users\gk616ph\documents\data analytics\python\flask projects\microblog\env\lib\site-packages\jinja2\_compat.py", line 28, in reraise
    raise value.with_traceback(tb)
  File "C:\Users\GK616PH\Documents\Data Analytics\Python\Flask projects\microblog\app\templates\login.html", line 1, in top-level template code
    {% extends "base.html" %}
  File "C:\Users\GK616PH\Documents\Data Analytics\Python\Flask projects\microblog\app\templates\base.html", line 31, in top-level template code
    {% block content %}{% endblock %}
  File "C:\Users\GK616PH\Documents\Data Analytics\Python\Flask projects\microblog\app\templates\login.html", line 25, in block "content"
    <a href="{{ url_for('reset_password_request') }}">Click to Reset It</a>
  File "c:\users\gk616ph\documents\data analytics\python\flask projects\microblog\env\lib\site-packages\flask\helpers.py", line 370, in url_for
    return appctx.app.handle_url_build_error(error, endpoint, values)
  File "c:\users\gk616ph\documents\data analytics\python\flask projects\microblog\env\lib\site-packages\flask\app.py", line 2215, in handle_url_build_error
    reraise(exc_type, exc_value, tb)
  File "c:\users\gk616ph\documents\data analytics\python\flask projects\microblog\env\lib\site-packages\flask\_compat.py", line 39, in reraise
    raise value
  File "c:\users\gk616ph\documents\data analytics\python\flask projects\microblog\env\lib\site-packages\flask\helpers.py", line 358, in url_for
    endpoint, values, method=method, force_external=external
  File "c:\users\gk616ph\documents\data analytics\python\flask projects\microblog\env\lib\site-packages\werkzeug\routing.py", line 2179, in build
    raise BuildError(endpoint, values, method, self)
werkzeug.routing.BuildError: Could not build url for endpoint 'reset_password_request'. Did you mean 'edit_profile' instead?
2020-04-12 21:49:47,864 INFO: Microblog startup [in C:\Users\GK616PH\Documents\Data Analytics\Python\Flask projects\microblog\app\__init__.py:45]
2020-04-12 21:49:51,412 ERROR: Exception on /login [GET] [in c:\users\gk616ph\documents\data analytics\python\flask projects\microblog\env\lib\site-packages\flask\app.py:1891]
Traceback (most recent call last):
  File "c:\users\gk616ph\documents\data analytics\python\flask projects\microblog\env\lib\site-packages\flask\app.py", line 2446, in wsgi_app
    response = self.full_dispatch_request()
  File "c:\users\gk616ph\documents\data analytics\python\flask projects\microblog\env\lib\site-packages\flask\app.py", line 1951, in full_dispatch_request
    rv = self.handle_user_exception(e)
  File "c:\users\gk616ph\documents\data analytics\python\flask projects\microblog\env\lib\site-packages\flask\app.py", line 1820, in handle_user_exception
    reraise(exc_type, exc_value, tb)
  File "c:\users\gk616ph\documents\data analytics\python\flask projects\microblog\env\lib\site-packages\flask\_compat.py", line 39, in reraise
    raise value
  File "c:\users\gk616ph\documents\data analytics\python\flask projects\microblog\env\lib\site-packages\flask\app.py", line 1949, in full_dispatch_request
    rv = self.dispatch_request()
  File "c:\users\gk616ph\documents\data analytics\python\flask projects\microblog\env\lib\site-packages\flask\app.py", line 1935, in dispatch_request
    return self.view_functions[rule.endpoint](**req.view_args)
  File "C:\Users\GK616PH\Documents\Data Analytics\Python\Flask projects\microblog\app\routes.py", line 69, in login
    return render_template('login.html', title='Sign In', form=form)
  File "c:\users\gk616ph\documents\data analytics\python\flask projects\microblog\env\lib\site-packages\flask\templating.py", line 140, in render_template
    ctx.app,
  File "c:\users\gk616ph\documents\data analytics\python\flask projects\microblog\env\lib\site-packages\flask\templating.py", line 120, in _render
    rv = template.render(context)
  File "c:\users\gk616ph\documents\data analytics\python\flask projects\microblog\env\lib\site-packages\jinja2\environment.py", line 1090, in render
    self.environment.handle_exception()
  File "c:\users\gk616ph\documents\data analytics\python\flask projects\microblog\env\lib\site-packages\jinja2\environment.py", line 832, in handle_exception
    reraise(*rewrite_traceback_stack(source=source))
  File "c:\users\gk616ph\documents\data analytics\python\flask projects\microblog\env\lib\site-packages\jinja2\_compat.py", line 28, in reraise
    raise value.with_traceback(tb)
  File "C:\Users\GK616PH\Documents\Data Analytics\Python\Flask projects\microblog\app\templates\login.html", line 1, in top-level template code
    {% extends "base.html" %}
  File "C:\Users\GK616PH\Documents\Data Analytics\Python\Flask projects\microblog\app\templates\base.html", line 31, in top-level template code
    {% block content %}{% endblock %}
  File "C:\Users\GK616PH\Documents\Data Analytics\Python\Flask projects\microblog\app\templates\login.html", line 27, in block "content"
    <a href="{{ url_for('reset_password_request') }}">Click to Reset It</a>
  File "c:\users\gk616ph\documents\data analytics\python\flask projects\microblog\env\lib\site-packages\flask\helpers.py", line 370, in url_for
    return appctx.app.handle_url_build_error(error, endpoint, values)
  File "c:\users\gk616ph\documents\data analytics\python\flask projects\microblog\env\lib\site-packages\flask\app.py", line 2215, in handle_url_build_error
    reraise(exc_type, exc_value, tb)
  File "c:\users\gk616ph\documents\data analytics\python\flask projects\microblog\env\lib\site-packages\flask\_compat.py", line 39, in reraise
    raise value
  File "c:\users\gk616ph\documents\data analytics\python\flask projects\microblog\env\lib\site-packages\flask\helpers.py", line 358, in url_for
    endpoint, values, method=method, force_external=external
  File "c:\users\gk616ph\documents\data analytics\python\flask projects\microblog\env\lib\site-packages\werkzeug\routing.py", line 2179, in build
    raise BuildError(endpoint, values, method, self)
werkzeug.routing.BuildError: Could not build url for endpoint 'reset_password_request'. Did you mean 'edit_profile' instead?
